# Workflow Execution - COMPLETE FIX

## Problems Identified & Fixed

### Problem 1: OpenAI Token Limit Error
```
‚ùå ORCHESTRATOR: REAL workflow execution failed: LLM error for AI Assistant 1: max_tokens is too large: 5000. This model supports at most 4096 completion tokens, whereas you provided 5000.
```

**Root Cause**: The workflow was trying to use `max_tokens=5000` but GPT-4-turbo only supports a maximum of 4096 completion tokens.

**Fix Applied**: 
- Added token limit validation in `get_llm_provider()` method
- Applied model-specific token caps:
  - GPT-4 models: 4096 max tokens
  - GPT-3.5 models: 4096 max tokens  
  - Other models: 2048 max tokens (safe default)

### Problem 2: sync_to_async Error
```
‚ùå SIMPLE: REAL workflow execution failed: sync_to_async can only be applied to sync functions.
```

**Root Cause**: The `sync_to_async()` decorator was being applied to `async def` functions instead of `def` (sync) functions.

**Fix Applied**:
- Changed `async def update_workflow_stats():` to `def update_workflow_stats():`
- Changed `async def update_failed_stats():` to `def update_failed_stats():`
- These functions are now properly synchronous and can be wrapped with `sync_to_async`

## Files Modified

### `/backend/agent_orchestration/conversation_orchestrator.py`
1. **Enhanced `get_llm_provider()` method** with token limit validation
2. **Fixed `execute_workflow()` method** sync_to_async usage  
3. **Added model-specific token limits** to prevent API errors

## Code Changes Summary

```python
# Before (BROKEN):
max_tokens = node_data.get('max_tokens', 2048)  # Could be 5000, causing error
async def update_workflow_stats():  # Wrong - async function with sync_to_async
    # ... code ...

# After (FIXED):  
max_tokens = min(node_data.get('max_tokens', 2048), 4096)  # Capped at 4096
def update_workflow_stats():  # Correct - sync function with sync_to_async  
    # ... code ...
```

## Testing Instructions

1. **Restart Django backend server**
2. **Navigate to Agent Orchestration page**
3. **Create/use existing workflow**: Start ‚Üí AI Assistant ‚Üí End  
4. **Click Execute button**

## Expected Result
‚úÖ **Workflow should execute successfully** without either error:
- No more "max_tokens is too large" errors
- No more "sync_to_async can only be applied to sync functions" errors

## Status
üéØ **COMPLETE FIX APPLIED** - Ready for testing

Both root causes have been identified and resolved. The workflow execution should now work properly.
